<?xml version="1.0" ?>
<robot name="omo_r1" xmlns:xacro="http://ros.org/wiki/xacro">
  <xacro:include filename="$(find omo_r1_description)/urdf/common_properties.xacro"/>

  <link name="omo/base_footprint"/>

  <joint name="base_joint" type="fixed">
    <parent link="omo/base_footprint"/>
    <child link="omo/base_link" />
    <origin xyz="0 0.0 0.07" rpy="0 0 0.0"/>
  </joint>

  <link name="omo/base_link">
    <visual>
      <origin xyz="0.097 0.276 0.19" rpy="3.14 0 -1.57"/>
      <geometry>
        <mesh filename="package://omo_r1_description/meshes/bases/omo_r1_body.stl" scale="0.001 0.001 0.001"/>
      </geometry>
      <material name="light_black"/>
    </visual>

    <collision>
      <origin xyz="0.097 0.276 0.19" rpy="3.14 0 -1.57"/>
      <geometry>
        <mesh filename="package://omo_r1_description/meshes/bases/omo_r1_body.stl" scale="0.001 0.001 0.001"/>
      </geometry>
    </collision>

    <inertial>
      <origin xyz="-0.028 0 0" rpy="0 0 0"/>
      <mass value="8.2573504"/>
      <inertia ixx="2.2124416e-02" ixy="-1.2294101e-04" ixz="3.4938785e-04"
               iyy="2.1193702e-02" iyz="-5.0120904e-05"
               izz="2.0064271e-02" />
    </inertial>
  </link>

  <joint name="wheel_left_joint" type="continuous">
    <parent link="omo/base_link"/>
    <child link="omo/wheel_left_link"/>
    <origin xyz="0.0 0.275 0.037" rpy="0.0 0.0 0"/>
    <axis xyz="0 1 0"/>
  </joint>

  <link name="omo/wheel_left_link">
    <visual>
      <origin xyz="-0.1105 -0.06 0.1104" rpy="-1.57 0 0"/>
      <geometry>
        <mesh filename="package://omo_r1_description/meshes/wheels/omo_r1_wheel.stl" scale="0.001 0.001 0.001"/>
      </geometry>
      <material name="dark"/>
    </visual>

    <collision>
      <origin xyz="-0.1105 -0.06 0.1104" rpy="-1.57 0 0"/>
      <geometry>
        <mesh filename="package://omo_r1_description/meshes/wheels/omo_r1_wheel.stl" scale="0.001 0.001 0.001"/>
      </geometry>
    </collision>

    <inertial>
      <origin xyz="0 0 0" />
      <mass value="2.8498940" />
      <inertia ixx="1.1175580e-03" ixy="-4.2369783e-08" ixz="-5.9381719e-07"
               iyy="1.1192413e-03" iyz="-1.4400107e-08"
               izz="2.0712558e-03" />
      </inertial>
  </link>

  <joint name="wheel_right_joint" type="continuous">
    <parent link="omo/base_link"/>
    <child link="omo/wheel_right_link"/>
    <origin xyz="0.0 -0.275 0.037" rpy="0.0 0 0"/>
    <axis xyz="0 1 0"/>
  </joint>

  <link name="omo/wheel_right_link">
    <visual>
      <origin xyz="-0.110 0.06 -0.1103" rpy="1.57 0 0"/>
      <geometry>
        <mesh filename="package://omo_r1_description/meshes/wheels/omo_r1_wheel.stl" scale="0.001 0.001 0.001"/>
      </geometry>
      <material name="dark"/>
    </visual>

    <collision>
      <origin xyz="-0.110 0.06 -0.1103" rpy="1.57 0 0"/>
      <geometry>
        <mesh filename="package://omo_r1_description/meshes/wheels/omo_r1_wheel.stl" scale="0.001 0.001 0.001"/>
      </geometry>
    </collision>

    <inertial>
      <origin xyz="0 0 0" />
      <mass value="2.8498940" />
      <inertia ixx="1.1175580e-03" ixy="-4.2369783e-08" ixz="-5.9381719e-07"
               iyy="1.1192413e-03" iyz="-1.4400107e-08"
               izz="2.0712558e-03" />
      </inertial>
  </link>

  <joint name="caster_back_right_joint" type="fixed">
    <parent link="omo/base_link"/>
    <child link="omo/caster_back_right_link"/>
    <origin xyz="-0.33 -0.148 0.06" rpy="0 0 0"/>
  </joint>

  <link name="omo/caster_back_right_link">
    <collision>
      <origin xyz="0 0.000 -0.133" rpy="0 0 0"/>
      <geometry>
        <box size="0.01 0.01 0.01"/>
      </geometry>
    </collision>

    <inertial>
      <origin xyz="0 0 0" />
      <mass value="0.000005" />
      <inertia ixx="0.000001" ixy="0.0" ixz="0.0"
               iyy="0.000001" iyz="0.0"
               izz="0.000001" />
    </inertial>
  </link>

  <joint name="caster_back_left_joint" type="fixed">
    <parent link="omo/base_link"/>
    <child link="omo/caster_back_left_link"/>
    <origin xyz="-0.33 0.148 0.06" rpy="0 0 0"/>
  </joint>

  <link name="omo/caster_back_left_link">
    <collision>
      <origin xyz="0 0.000 -0.133" rpy="0 0 0"/>
      <geometry>
        <box size="0.01 0.01 0.01"/>
      </geometry>
    </collision>

    <inertial>
      <origin xyz="0 0 0" />
      <mass value="0.000005" />
      <inertia ixx="0.000001" ixy="0.0" ixz="0.0"
               iyy="0.000001" iyz="0.0"
               izz="0.000001" />
    </inertial>
  </link>
  
  <joint name="scan_joint" type="fixed">
    <parent link="omo/base_link"/>
    <child link="omo/laser"/>
    <origin xyz="0.06 0 0.230" rpy="3.141592 3.141592 0.0"/>
  </joint>

  <link name="omo/laser">
    <visual>
      <origin xyz="0 0 0.0" rpy="0.0 0 0.0"/>
      <geometry>
        <mesh filename="package://omo_r1_description/meshes/sensors/omo_r1_lidar.stl" scale="0.001 0.001 0.001"/>
      </geometry>
      <material name="dark"/>
    </visual>

    <collision>
      <origin xyz="0 0 0.0" rpy="0.0 0 0.0"/>
      <geometry>
        <mesh filename="package://omo_r1_description/meshes/sensors/omo_r1_lidar.stl" scale="0.001 0.001 0.001"/>
      </geometry>
    </collision>

    <inertial>
      <mass value="0.114" />
      <origin xyz="0 0 0" />
      <inertia ixx="0.001" ixy="0.0" ixz="0.0"
               iyy="0.001" iyz="0.0"
               izz="0.001" />
    </inertial>
  </link>S


  <!-- <joint name="camera_joint" type="fixed">
    <origin xyz="0.06 0.1 0.50" rpy="-1.5758 0.0 -1.5758"/>
    <parent link="omo/base_link"/>
    <child link="omo/camera_link"/>
  </joint>

  <link name="omo/camera_link">
    <visual>
      <origin xyz="0 0 0.0" rpy="1.5758 0.0 1.5758"/>
      <geometry>
        <mesh filename="package://omo_r1_description/meshes/sensors/omo_r1_camera.stl" scale="0.001 0.001 0.001"/>
      </geometry>
      <material name="dark"/>
    </visual>

    <collision>
      <origin xyz="0 0 0.0" rpy="1.5758 0.0 1.5758"/>
      <geometry>
        <mesh filename="package://omo_r1_description/meshes/sensors/omo_r1_camera.stl" scale="0.001 0.001 0.001"/>
      </geometry>
    </collision>
  </link> -->

  <!--joint name="camera_rgb_joint" type="fixed">
    <origin xyz="0.03 0.0 0.0" rpy="0 0 0"/>
    <parent link="omo/camera_link"/>
    <child link="omo/camera_rgb_frame"/>
  </joint>
  <link name="omo/camera_rgb_frame"/>

  <joint name="camera_rgb_optical_joint" type="fixed">
    <origin xyz="0 0 0" rpy="-1.57 0 -1.57"/>
    <parent link="omo/camera_rgb_frame"/>
    <child link="omo/camera_rgb_optical_frame"/>
  </joint>
  <link name="omo/camera_rgb_optical_frame"/-->
</robot>
